<?xml version="1.0"?>
<robot name="canadarm2" xmlns:xacro="http://www.ros.org/wiki/xacro">

  <!-- CANADARM2 -->
  <xacro:macro name="canadarm2" params=" parent:='' ">

  <link name="pdgf"/>
  <link name="pdgf_forward"/>
  <joint name="joint_pdgf_forward" type="fixed">
      <origin rpy="0 0 3.1416" xyz="0 0 0"/>
      <parent link="canadarm2_base"/>
      <child link="pdgf_forward"/>
  </joint>

  <!-- ******* Link Base *******  -->
  <link name="canadarm2_base">
   <inertial>
     <origin xyz="0 0 0.0" rpy="0 0 0"/>
     <mass value="1"/>
     <inertia ixx="100"  ixy="0"  ixz="0" iyy="100" iyz="0" izz="100" />
   </inertial>

   <visual>
     <origin xyz="0 0 0" rpy="0.35691983 0.0 0.572468" />
     <geometry>
       <mesh filename="package://iss_description/meshes/canadarm2/base.dae" scale="1 1 1"/>
     </geometry>
   </visual>

   <collision>
     <origin xyz="0 0 0" rpy="0 0 0"/>
     <geometry>
       <mesh filename="package://iss_description/meshes/canadarm2/base.dae" scale="1 1 1"/>
     </geometry>
   </collision>
  </link>

  <!-- ******* Link 1 *******  -->
  <link name="canadarm2_link_1">
    <inertial>
      <origin xyz="0 0 0.0" rpy="0 0 0"/>
      <mass value="1"/>
      <inertia ixx="100"  ixy="0"  ixz="0" iyy="100" iyz="0" izz="100" />
    </inertial>

    <visual>
      <origin xyz="0 0 0" rpy="0.0 -0.488692 0.663225" /> <!-- Blender: 0 -28 38-->
      <geometry>
        <mesh filename="package://iss_description/meshes/canadarm2/link_1.dae" scale="1 1 1"/>
      </geometry>
    </visual>

    <collision>
      <origin xyz="0 0 0" rpy="0.0 -0.488692 0.663225"/>
      <geometry>
        <mesh filename="package://iss_description/meshes/canadarm2/link_1.dae" scale="1 1 1"/>
      </geometry>
    </collision>
   </link>

  <!-- ******* Link 2 *******  -->
  <link name="canadarm2_link_2">
    <inertial>
      <origin xyz="0 0 0.0" rpy="0 0 0"/>
      <mass value="1"/>
      <inertia ixx="100"  ixy="0"  ixz="0" iyy="100" iyz="0" izz="100" />
    </inertial>

    <visual>
      <origin xyz="0 0 0" rpy="0 -0.49131018 0" /> <!-- Blender: 0.0 -28.15 0.0-->
      <geometry>
        <mesh filename="package://iss_description/meshes/canadarm2/link_2.dae" scale="1 1 1"/>
      </geometry>
    </visual>

    <collision>
      <origin xyz="0 0 0" rpy="0 -0.49131018 0"/>
      <geometry>
        <mesh filename="package://iss_description/meshes/canadarm2/link_2.dae" scale="1 1 1"/>
      </geometry>
    </collision>
   </link>
   
  <!-- ******* Link 3 *******  -->
  <link name="canadarm2_link_3">
    <inertial>
      <origin xyz="0 0 0.0" rpy="0 0 0"/>
      <mass value="1"/>
      <inertia ixx="100"  ixy="0"  ixz="0" iyy="100" iyz="0" izz="100" />
    </inertial>

    <visual>
      <origin xyz="0 0 0" rpy="0 0 0" />
      <geometry>
        <mesh filename="package://iss_description/meshes/canadarm2/link_3.dae" scale="1 1 1"/>
      </geometry>
    </visual>

    <collision>
      <origin xyz="0 0 0" rpy="0 0 0"/>
      <geometry>
        <mesh filename="package://iss_description/meshes/canadarm2/link_3.dae" scale="1 1 1"/>
      </geometry>
    </collision>
   </link>


  <!-- ******* Link 4 *******  -->
  <link name="canadarm2_link_4">
    <inertial>
      <origin xyz="0 0 0.0" rpy="0 0 0"/>
      <mass value="1"/>
      <inertia ixx="100"  ixy="0"  ixz="0" iyy="100" iyz="0" izz="100" />
    </inertial>

    <visual>
      <origin xyz="0 0 0" rpy="0 0 0" />
      <geometry>
        <mesh filename="package://iss_description/meshes/canadarm2/link_4.dae" scale="1 1 1"/>
      </geometry>
    </visual>

    <collision>
      <origin xyz="0 0 0" rpy="0 0 0"/>
      <geometry>
        <mesh filename="package://iss_description/meshes/canadarm2/link_4.dae" scale="1 1 1"/>
      </geometry>
    </collision>
   </link>

  <!-- ******* Link 5 *******  -->
  <link name="canadarm2_link_5">
    <inertial>
      <origin xyz="0 0 0.0" rpy="0 0 0"/>
      <mass value="1"/>
      <inertia ixx="100"  ixy="0"  ixz="0" iyy="100" iyz="0" izz="100" />
    </inertial>

    <visual>
      <origin xyz="0 0 0" rpy="0 0 0" />
      <geometry>
        <mesh filename="package://iss_description/meshes/canadarm2/link_5.dae" scale="1 1 1"/>
      </geometry>
    </visual>

    <collision>
      <origin xyz="0 0 0" rpy="0 0 0"/>
      <geometry>
        <mesh filename="package://iss_description/meshes/canadarm2/link_5.dae" scale="1 1 1"/>
      </geometry>
    </collision>
   </link>
   
  <!-- ******* Link 6 *******  -->
  <link name="canadarm2_link_6">
    <inertial>
      <origin xyz="0 0 0.0" rpy="0 0 0"/>
      <mass value="1"/>
      <inertia ixx="100"  ixy="0"  ixz="0" iyy="100" iyz="0" izz="100" />
    </inertial>

    <visual>
      <origin xyz="0 0 0" rpy="0 0 0" />
      <geometry>
        <mesh filename="package://iss_description/meshes/canadarm2/link_6.dae" scale="1 1 1"/>
      </geometry>
    </visual>

    <collision>
      <origin xyz="0 0 0" rpy="0 0 0"/>
      <geometry>
        <mesh filename="package://iss_description/meshes/canadarm2/link_6.dae" scale="1 1 1"/>
      </geometry>
    </collision>
   </link>

  <!-- ******* Link 7 *******  -->
  <link name="canadarm2_link_7">
    <inertial>
      <origin xyz="0 0 0.0" rpy="0 0 0"/>
      <mass value="1"/>
      <inertia ixx="100"  ixy="0"  ixz="0" iyy="100" iyz="0" izz="100" />
    </inertial>

    <visual>
      <origin xyz="0 0 0" rpy="0 0 0" />
      <geometry>
        <mesh filename="package://iss_description/meshes/canadarm2/link_7.dae" scale="1 1 1"/>
      </geometry>
    </visual>

    <collision>
      <origin xyz="0 0 0" rpy="0 0 0"/>
      <geometry>
        <mesh filename="package://iss_description/meshes/canadarm2/link_7.dae" scale="1 1 1"/>
      </geometry>
    </collision>
   </link>   

  <joint name="joint_pdgf" type="fixed">
      <origin rpy="0 0 0" xyz="-1.4347 -0.19847 1.5901"/>
      <parent link="${parent}"/>
      <child link="pdgf"/>
  </joint>
  

  <joint name="joint_canadarm2_base" type="fixed">
      <origin rpy="-0.35691983 0.0 -0.572468" xyz="0 0 0"/> 
      <parent link="pdgf"/>
      <child link="canadarm2_base"/>
  </joint>

  <!-- joint 1 -->
  <joint name="joint_canadarm2_1" type="revolute">
      <origin rpy="0 0 0" xyz="0.0 -1.2388 0.0"/> <!-- -0.66927 -0.97994 0.3556 -->
      <parent link="canadarm2_base"/>
      <child link="canadarm2_link_1"/>
      <axis xyz="0 1 0"/>
      <limit effort="1000.0" lower="-3.1416" upper="3.1416" velocity="0.5"/>
  </joint>

  <!-- joint 2 -->
  <joint name="joint_canadarm2_2" type="revolute">
      <origin rpy="0 0 0" xyz="-0.005874 -0.22963 0.35801"/>
      <parent link="canadarm2_link_1"/>
      <child link="canadarm2_link_2"/>
      <axis xyz="0 0 1"/>
      <limit effort="1000.0" lower="-3.1416" upper="3.1416" velocity="0.5"/>
  </joint>

  <!-- joint 3 -->
  <joint name="joint_canadarm2_3" type="revolute">
      <origin rpy="0 0 0" xyz="0.13387 -0.31415 0.25363"/>
      <parent link="canadarm2_link_2"/>
      <child link="canadarm2_link_3"/>
      <axis xyz="0 1 0"/>
      <limit effort="1000.0" lower="-3.1416" upper="3.1416" velocity="0.5"/>
  </joint>
  
  <!-- joint 4 -->
  <joint name="joint_canadarm2_4" type="revolute">
      <origin rpy="0 0 0" xyz="-7.3435 -0.57517 0.004392"/>
      <parent link="canadarm2_link_3"/>
      <child link="canadarm2_link_4"/>
      <axis xyz="0 1 0"/>
      <limit effort="1000.0" lower="-3.1416" upper="3.1416" velocity="0.5"/>
  </joint>  
  
  <!-- joint 5 -->
  <joint name="joint_canadarm2_5" type="revolute">
      <origin rpy="0 0 0" xyz="0.004395 -0.57517 7.3435"/>
      <parent link="canadarm2_link_4"/>
      <child link="canadarm2_link_5"/>
      <axis xyz="0 1 0"/>
      <limit effort="1000.0" lower="-3.1416" upper="3.1416" velocity="0.5"/>
  </joint>   
  
  <!-- joint 6 -->
  <joint name="joint_canadarm2_6" type="revolute">
      <origin rpy="0 0 0" xyz="-0.28758 -0.3134 0.002192"/>
      <parent link="canadarm2_link_5"/>
      <child link="canadarm2_link_6"/>
      <axis xyz="1 0 0"/>
      <limit effort="1000.0" lower="-3.1416" upper="3.1416" velocity="0.5"/>
  </joint> 
  
  <!-- joint 7 -->
  <joint name="joint_canadarm2_7" type="revolute">
      <origin rpy="0 0 0" xyz="-0.31341 -0.002199 0.28759"/>
      <parent link="canadarm2_link_6"/>
      <child link="canadarm2_link_7"/>
      <axis xyz="0 0 1"/>
      <limit effort="1000.0" lower="-3.1416" upper="3.1416" velocity="0.5"/>
  </joint> 
  
 </xacro:macro> 
    
</robot>
